[2022-08-13 09:00:46,500] {taskinstance.py:1179} INFO - Dependencies all met for <TaskInstance: craw.cr2 manual__2022-08-13T09:00:44.665858+00:00 [queued]>
[2022-08-13 09:00:46,520] {taskinstance.py:1179} INFO - Dependencies all met for <TaskInstance: craw.cr2 manual__2022-08-13T09:00:44.665858+00:00 [queued]>
[2022-08-13 09:00:46,521] {taskinstance.py:1376} INFO - 
--------------------------------------------------------------------------------
[2022-08-13 09:00:46,522] {taskinstance.py:1377} INFO - Starting attempt 1 of 2
[2022-08-13 09:00:46,522] {taskinstance.py:1378} INFO - 
--------------------------------------------------------------------------------
[2022-08-13 09:00:46,550] {taskinstance.py:1397} INFO - Executing <Task(PythonOperator): cr2> on 2022-08-13 09:00:44.665858+00:00
[2022-08-13 09:00:46,558] {standard_task_runner.py:52} INFO - Started process 3966 to run task
[2022-08-13 09:00:46,563] {standard_task_runner.py:79} INFO - Running: ['***', 'tasks', 'run', 'craw', 'cr2', 'manual__2022-08-13T09:00:44.665858+00:00', '--job-id', '53', '--raw', '--subdir', 'DAGS_FOLDER/newtest.py', '--cfg-path', '/tmp/tmp_rv_6ng6', '--error-file', '/tmp/tmpnxrc688m']
[2022-08-13 09:00:46,565] {standard_task_runner.py:80} INFO - Job 53: Subtask cr2
[2022-08-13 09:00:46,670] {task_command.py:371} INFO - Running <TaskInstance: craw.cr2 manual__2022-08-13T09:00:44.665858+00:00 [running]> on host cdb6935da655
[2022-08-13 09:00:46,806] {taskinstance.py:1591} INFO - Exporting the following env vars:
AIRFLOW_CTX_DAG_OWNER=***
AIRFLOW_CTX_DAG_ID=craw
AIRFLOW_CTX_TASK_ID=cr2
AIRFLOW_CTX_EXECUTION_DATE=2022-08-13T09:00:44.665858+00:00
AIRFLOW_CTX_TRY_NUMBER=1
AIRFLOW_CTX_DAG_RUN_ID=manual__2022-08-13T09:00:44.665858+00:00
[2022-08-13 09:00:46,810] {logger.py:11} INFO - ====== WebDriver manager ======
[2022-08-13 09:00:46,946] {logger.py:11} INFO - Get LATEST chromedriver version for google-chrome 104.0.5112
[2022-08-13 09:00:47,336] {logger.py:11} INFO - Driver [/home/***/.wdm/drivers/chromedriver/linux64/104.0.5112/chromedriver] found in cache
[2022-08-13 09:02:17,084] {base.py:68} INFO - Using connection ID 'mysql' for task execution.
[2022-08-13 09:02:17,088] {dbapi.py:231} INFO - Running statement: INSERT INTO info (image,name,price,review) VALUES (%s, %s, %s, %s);, parameters: None
[2022-08-13 09:02:17,090] {taskinstance.py:1909} ERROR - Task failed with exception
Traceback (most recent call last):
  File "/home/airflow/.local/lib/python3.7/site-packages/airflow/operators/python.py", line 171, in execute
    return_value = self.execute_callable()
  File "/home/airflow/.local/lib/python3.7/site-packages/airflow/operators/python.py", line 189, in execute_callable
    return self.python_callable(*self.op_args, **self.op_kwargs)
  File "/opt/airflow/dags/newtest.py", line 94, in crawling
    mysql_hook.run(insert_mysql,(image,name,price,review))
  File "/home/airflow/.local/lib/python3.7/site-packages/airflow/hooks/dbapi.py", line 211, in run
    self._run_command(cur, sql_statement, parameters)
  File "/home/airflow/.local/lib/python3.7/site-packages/airflow/hooks/dbapi.py", line 235, in _run_command
    cur.execute(sql_statement)
  File "/home/airflow/.local/lib/python3.7/site-packages/pymysql/cursors.py", line 148, in execute
    result = self._query(query)
  File "/home/airflow/.local/lib/python3.7/site-packages/pymysql/cursors.py", line 310, in _query
    conn.query(q)
  File "/home/airflow/.local/lib/python3.7/site-packages/pymysql/connections.py", line 548, in query
    self._affected_rows = self._read_query_result(unbuffered=unbuffered)
  File "/home/airflow/.local/lib/python3.7/site-packages/pymysql/connections.py", line 775, in _read_query_result
    result.read()
  File "/home/airflow/.local/lib/python3.7/site-packages/pymysql/connections.py", line 1156, in read
    first_packet = self.connection._read_packet()
  File "/home/airflow/.local/lib/python3.7/site-packages/pymysql/connections.py", line 725, in _read_packet
    packet.raise_for_error()
  File "/home/airflow/.local/lib/python3.7/site-packages/pymysql/protocol.py", line 221, in raise_for_error
    err.raise_mysql_exception(self._data)
  File "/home/airflow/.local/lib/python3.7/site-packages/pymysql/err.py", line 143, in raise_mysql_exception
    raise errorclass(errno, errval)
pymysql.err.ProgrammingError: (1064, "You have an error in your SQL syntax; check the manual that corresponds to your MySQL server version for the right syntax to use near '%s, %s, %s, %s)' at line 1")
[2022-08-13 09:02:17,117] {taskinstance.py:1420} INFO - Marking task as UP_FOR_RETRY. dag_id=craw, task_id=cr2, execution_date=20220813T090044, start_date=20220813T090046, end_date=20220813T090217
[2022-08-13 09:02:17,165] {standard_task_runner.py:97} ERROR - Failed to execute job 53 for task cr2 ((1064, "You have an error in your SQL syntax; check the manual that corresponds to your MySQL server version for the right syntax to use near '%s, %s, %s, %s)' at line 1"); 3966)
[2022-08-13 09:02:17,214] {local_task_job.py:221} WARNING - State of this instance has been externally set to up_for_retry. Terminating instance.
[2022-08-13 09:02:17,235] {process_utils.py:129} INFO - Sending Signals.SIGTERM to group 3966. PIDs of all processes in the group: [4020, 4033, 4042, 4044, 4065, 4068, 4129, 4186, 4239, 4128, 3966]
[2022-08-13 09:02:17,236] {process_utils.py:80} INFO - Sending the signal Signals.SIGTERM to group 3966
[2022-08-13 09:02:17,291] {process_utils.py:75} INFO - Process psutil.Process(pid=4042, status='terminated', started='09:00:47') (4042) terminated with exit code None
[2022-08-13 09:02:17,292] {process_utils.py:75} INFO - Process psutil.Process(pid=4033, status='terminated', started='09:00:47') (4033) terminated with exit code None
[2022-08-13 09:02:17,320] {process_utils.py:75} INFO - Process psutil.Process(pid=4239, status='terminated', started='09:01:50') (4239) terminated with exit code None
[2022-08-13 09:02:17,321] {process_utils.py:75} INFO - Process psutil.Process(pid=4020, status='terminated', started='09:00:46') (4020) terminated with exit code None
[2022-08-13 09:02:17,322] {process_utils.py:75} INFO - Process psutil.Process(pid=3966, status='terminated', exitcode=1, started='09:00:45') (3966) terminated with exit code 1
[2022-08-13 09:02:17,323] {process_utils.py:75} INFO - Process psutil.Process(pid=4186, status='terminated', started='09:00:47') (4186) terminated with exit code None
[2022-08-13 09:02:17,324] {process_utils.py:75} INFO - Process psutil.Process(pid=4044, status='terminated', started='09:00:47') (4044) terminated with exit code None
[2022-08-13 09:02:17,326] {process_utils.py:75} INFO - Process psutil.Process(pid=4129, status='terminated', started='09:00:47') (4129) terminated with exit code None
[2022-08-13 09:02:17,327] {process_utils.py:75} INFO - Process psutil.Process(pid=4128, status='terminated', started='09:00:47') (4128) terminated with exit code None
[2022-08-13 09:02:17,327] {process_utils.py:75} INFO - Process psutil.Process(pid=4068, status='terminated', started='09:00:47') (4068) terminated with exit code None
[2022-08-13 09:02:17,328] {process_utils.py:75} INFO - Process psutil.Process(pid=4065, status='terminated', started='09:00:47') (4065) terminated with exit code None
