[2022-08-18 04:32:39,563] {taskinstance.py:1179} INFO - Dependencies all met for <TaskInstance: craw.cr4 manual__2022-08-18T04:32:34.652409+00:00 [queued]>
[2022-08-18 04:32:39,609] {taskinstance.py:1179} INFO - Dependencies all met for <TaskInstance: craw.cr4 manual__2022-08-18T04:32:34.652409+00:00 [queued]>
[2022-08-18 04:32:39,610] {taskinstance.py:1376} INFO - 
--------------------------------------------------------------------------------
[2022-08-18 04:32:39,611] {taskinstance.py:1377} INFO - Starting attempt 1 of 2
[2022-08-18 04:32:39,613] {taskinstance.py:1378} INFO - 
--------------------------------------------------------------------------------
[2022-08-18 04:32:39,669] {taskinstance.py:1397} INFO - Executing <Task(PythonOperator): cr4> on 2022-08-18 04:32:34.652409+00:00
[2022-08-18 04:32:39,682] {standard_task_runner.py:52} INFO - Started process 517 to run task
[2022-08-18 04:32:39,691] {standard_task_runner.py:79} INFO - Running: ['***', 'tasks', 'run', 'craw', 'cr4', 'manual__2022-08-18T04:32:34.652409+00:00', '--job-id', '167', '--raw', '--subdir', 'DAGS_FOLDER/newtest.py', '--cfg-path', '/tmp/tmp8sduyday', '--error-file', '/tmp/tmpzkvvezpi']
[2022-08-18 04:32:39,700] {standard_task_runner.py:80} INFO - Job 167: Subtask cr4
[2022-08-18 04:32:40,262] {task_command.py:371} INFO - Running <TaskInstance: craw.cr4 manual__2022-08-18T04:32:34.652409+00:00 [running]> on host d59619969b18
[2022-08-18 04:32:40,770] {taskinstance.py:1591} INFO - Exporting the following env vars:
AIRFLOW_CTX_DAG_OWNER=***
AIRFLOW_CTX_DAG_ID=craw
AIRFLOW_CTX_TASK_ID=cr4
AIRFLOW_CTX_EXECUTION_DATE=2022-08-18T04:32:34.652409+00:00
AIRFLOW_CTX_TRY_NUMBER=1
AIRFLOW_CTX_DAG_RUN_ID=manual__2022-08-18T04:32:34.652409+00:00
[2022-08-18 04:32:41,521] {base.py:68} INFO - Using connection ID 'mysql' for task execution.
[2022-08-18 04:32:41,559] {logger.py:11} INFO - ====== WebDriver manager ======
[2022-08-18 04:32:47,151] {logger.py:11} INFO - Get LATEST chromedriver version for google-chrome 104.0.5112
[2022-08-18 04:32:48,837] {logger.py:11} INFO - About to download new driver from https://chromedriver.storage.googleapis.com/104.0.5112.79/chromedriver_linux64.zip
[2022-08-18 04:33:35,521] {logger.py:11} INFO - Driver has been saved in cache [/home/***/.wdm/drivers/chromedriver/linux64/104.0.5112]
[2022-08-18 04:34:50,311] {logging_mixin.py:115} INFO - https://shopping-phinf.pstatic.net/main_2089989/20899895174.20190918142705.jpg?type=f140 로지텍 MX KEYS 104,100원 
[2022-08-18 04:35:14,377] {logging_mixin.py:115} INFO - https://shopping-phinf.pstatic.net/main_2336494/23364942490.20200706104104.jpg?type=f140 한성컴퓨터 GK787S OfficeMaster 체리 기계식키보드 79,900원 
[2022-08-18 04:35:14,405] {taskinstance.py:1909} ERROR - Task failed with exception
Traceback (most recent call last):
  File "/home/airflow/.local/lib/python3.7/site-packages/airflow/operators/python.py", line 171, in execute
    return_value = self.execute_callable()
  File "/home/airflow/.local/lib/python3.7/site-packages/airflow/operators/python.py", line 189, in execute_callable
    return self.python_callable(*self.op_args, **self.op_kwargs)
  File "/opt/airflow/dags/newtest.py", line 100, in crawling
    cursor.execute("INSERT INTO info VALUES (%s, %s, %s, %s);",(image,name,price,review))
  File "/home/airflow/.local/lib/python3.7/site-packages/pymysql/cursors.py", line 148, in execute
    result = self._query(query)
  File "/home/airflow/.local/lib/python3.7/site-packages/pymysql/cursors.py", line 310, in _query
    conn.query(q)
  File "/home/airflow/.local/lib/python3.7/site-packages/pymysql/connections.py", line 548, in query
    self._affected_rows = self._read_query_result(unbuffered=unbuffered)
  File "/home/airflow/.local/lib/python3.7/site-packages/pymysql/connections.py", line 775, in _read_query_result
    result.read()
  File "/home/airflow/.local/lib/python3.7/site-packages/pymysql/connections.py", line 1156, in read
    first_packet = self.connection._read_packet()
  File "/home/airflow/.local/lib/python3.7/site-packages/pymysql/connections.py", line 725, in _read_packet
    packet.raise_for_error()
  File "/home/airflow/.local/lib/python3.7/site-packages/pymysql/protocol.py", line 221, in raise_for_error
    err.raise_mysql_exception(self._data)
  File "/home/airflow/.local/lib/python3.7/site-packages/pymysql/err.py", line 143, in raise_mysql_exception
    raise errorclass(errno, errval)
pymysql.err.DataError: (1406, "Data too long for column 'name' at row 1")
[2022-08-18 04:35:14,685] {taskinstance.py:1420} INFO - Marking task as UP_FOR_RETRY. dag_id=craw, task_id=cr4, execution_date=20220818T043234, start_date=20220818T043239, end_date=20220818T043514
[2022-08-18 04:35:14,883] {standard_task_runner.py:97} ERROR - Failed to execute job 167 for task cr4 ((1406, "Data too long for column 'name' at row 1"); 517)
[2022-08-18 04:35:14,956] {local_task_job.py:156} INFO - Task exited with return code 1
[2022-08-18 04:35:15,160] {local_task_job.py:273} INFO - 0 downstream tasks scheduled from follow-on schedule check
