[2022-08-11 03:17:40,728] {taskinstance.py:1179} INFO - Dependencies all met for <TaskInstance: craw.cr1 manual__2022-08-11T02:28:35.663834+00:00 [queued]>
[2022-08-11 03:17:40,746] {taskinstance.py:1179} INFO - Dependencies all met for <TaskInstance: craw.cr1 manual__2022-08-11T02:28:35.663834+00:00 [queued]>
[2022-08-11 03:17:40,747] {taskinstance.py:1376} INFO - 
--------------------------------------------------------------------------------
[2022-08-11 03:17:40,747] {taskinstance.py:1377} INFO - Starting attempt 5 of 5
[2022-08-11 03:17:40,748] {taskinstance.py:1378} INFO - 
--------------------------------------------------------------------------------
[2022-08-11 03:17:40,779] {taskinstance.py:1397} INFO - Executing <Task(PythonOperator): cr1> on 2022-08-11 02:28:35.663834+00:00
[2022-08-11 03:17:40,790] {standard_task_runner.py:52} INFO - Started process 3756 to run task
[2022-08-11 03:17:40,796] {standard_task_runner.py:79} INFO - Running: ['***', 'tasks', 'run', 'craw', 'cr1', 'manual__2022-08-11T02:28:35.663834+00:00', '--job-id', '56', '--raw', '--subdir', 'DAGS_FOLDER/newtest.py', '--cfg-path', '/tmp/tmpwap64bwj', '--error-file', '/tmp/tmp_i9xcfup']
[2022-08-11 03:17:40,799] {standard_task_runner.py:80} INFO - Job 56: Subtask cr1
[2022-08-11 03:17:40,922] {task_command.py:371} INFO - Running <TaskInstance: craw.cr1 manual__2022-08-11T02:28:35.663834+00:00 [running]> on host d59619969b18
[2022-08-11 03:17:41,070] {taskinstance.py:1591} INFO - Exporting the following env vars:
AIRFLOW_CTX_DAG_OWNER=***
AIRFLOW_CTX_DAG_ID=craw
AIRFLOW_CTX_TASK_ID=cr1
AIRFLOW_CTX_EXECUTION_DATE=2022-08-11T02:28:35.663834+00:00
AIRFLOW_CTX_TRY_NUMBER=5
AIRFLOW_CTX_DAG_RUN_ID=manual__2022-08-11T02:28:35.663834+00:00
[2022-08-11 03:17:41,073] {logger.py:11} INFO - ====== WebDriver manager ======
[2022-08-11 03:17:41,238] {logger.py:11} INFO - Get LATEST chromedriver version for google-chrome 104.0.5112
[2022-08-11 03:17:41,989] {logger.py:11} INFO - Driver [/home/***/.wdm/drivers/chromedriver/linux64/104.0.5112/chromedriver] found in cache
[2022-08-11 03:20:19,534] {taskinstance.py:1909} ERROR - Task failed with exception
Traceback (most recent call last):
  File "/home/airflow/.local/lib/python3.7/site-packages/airflow/operators/python.py", line 171, in execute
    return_value = self.execute_callable()
  File "/home/airflow/.local/lib/python3.7/site-packages/airflow/operators/python.py", line 189, in execute_callable
    return self.python_callable(*self.op_args, **self.op_kwargs)
  File "/opt/airflow/dags/newtest.py", line 107, in craw1
    crawling(1,3)
  File "/opt/airflow/dags/newtest.py", line 93, in crawling
    lists.append((image, name, price, review))
NameError: name 'lists' is not defined
[2022-08-11 03:20:19,554] {taskinstance.py:1420} INFO - Marking task as FAILED. dag_id=craw, task_id=cr1, execution_date=20220811T022835, start_date=20220811T031740, end_date=20220811T032019
[2022-08-11 03:20:19,575] {standard_task_runner.py:97} ERROR - Failed to execute job 56 for task cr1 (name 'lists' is not defined; 3756)
[2022-08-11 03:20:19,604] {local_task_job.py:156} INFO - Task exited with return code 1
[2022-08-11 03:20:19,643] {local_task_job.py:273} INFO - 0 downstream tasks scheduled from follow-on schedule check
