[2022-08-18 05:50:07,150] {taskinstance.py:1179} INFO - Dependencies all met for <TaskInstance: craw.db manual__2022-08-18T04:38:28.162136+00:00 [queued]>
[2022-08-18 05:50:07,194] {taskinstance.py:1179} INFO - Dependencies all met for <TaskInstance: craw.db manual__2022-08-18T04:38:28.162136+00:00 [queued]>
[2022-08-18 05:50:07,195] {taskinstance.py:1376} INFO - 
--------------------------------------------------------------------------------
[2022-08-18 05:50:07,195] {taskinstance.py:1377} INFO - Starting attempt 3 of 4
[2022-08-18 05:50:07,196] {taskinstance.py:1378} INFO - 
--------------------------------------------------------------------------------
[2022-08-18 05:50:07,259] {taskinstance.py:1397} INFO - Executing <Task(PythonOperator): db> on 2022-08-18 04:38:28.162136+00:00
[2022-08-18 05:50:07,277] {standard_task_runner.py:52} INFO - Started process 2896 to run task
[2022-08-18 05:50:07,294] {standard_task_runner.py:79} INFO - Running: ['***', 'tasks', 'run', 'craw', 'db', 'manual__2022-08-18T04:38:28.162136+00:00', '--job-id', '217', '--raw', '--subdir', 'DAGS_FOLDER/newtest.py', '--cfg-path', '/tmp/tmp64d7xnl9', '--error-file', '/tmp/tmpxl1cuyj2']
[2022-08-18 05:50:07,298] {standard_task_runner.py:80} INFO - Job 217: Subtask db
[2022-08-18 05:50:07,662] {task_command.py:371} INFO - Running <TaskInstance: craw.db manual__2022-08-18T04:38:28.162136+00:00 [running]> on host 94a850521595
[2022-08-18 05:50:07,971] {taskinstance.py:1173} INFO - Dependencies not met for <TaskInstance: craw.db manual__2022-08-18T04:38:28.162136+00:00 [running]>, dependency 'Task Instance Not Running' FAILED: Task is in the running state
[2022-08-18 05:50:08,022] {taskinstance.py:1173} INFO - Dependencies not met for <TaskInstance: craw.db manual__2022-08-18T04:38:28.162136+00:00 [running]>, dependency 'Task Instance State' FAILED: Task is in the 'running' state.
[2022-08-18 05:50:08,027] {local_task_job.py:101} INFO - Task is not able to be run
[2022-08-18 05:50:08,399] {taskinstance.py:1591} INFO - Exporting the following env vars:
AIRFLOW_CTX_DAG_OWNER=***
AIRFLOW_CTX_DAG_ID=craw
AIRFLOW_CTX_TASK_ID=db
AIRFLOW_CTX_EXECUTION_DATE=2022-08-18T04:38:28.162136+00:00
AIRFLOW_CTX_TRY_NUMBER=3
AIRFLOW_CTX_DAG_RUN_ID=manual__2022-08-18T04:38:28.162136+00:00
[2022-08-18 05:50:08,471] {base.py:68} INFO - Using connection ID 'mysql' for task execution.
[2022-08-18 05:50:25,098] {logging_mixin.py:115} WARNING - Traceback (most recent call last):
[2022-08-18 05:50:25,099] {logging_mixin.py:115} WARNING -   File "/home/***/.local/lib/python3.7/site-packages/pyspark/serializers.py", line 458, in dumps
    return cloudpickle.dumps(obj, pickle_protocol)
[2022-08-18 05:50:25,099] {logging_mixin.py:115} WARNING -   File "/home/***/.local/lib/python3.7/site-packages/pyspark/cloudpickle/cloudpickle_fast.py", line 102, in dumps
    cp.dump(obj)
[2022-08-18 05:50:25,100] {logging_mixin.py:115} WARNING -   File "/home/***/.local/lib/python3.7/site-packages/pyspark/cloudpickle/cloudpickle_fast.py", line 602, in dump
    return Pickler.dump(self, obj)
[2022-08-18 05:50:25,100] {logging_mixin.py:115} WARNING -   File "/usr/local/lib/python3.7/pickle.py", line 437, in dump
    self.save(obj)
[2022-08-18 05:50:25,101] {logging_mixin.py:115} WARNING -   File "/usr/local/lib/python3.7/pickle.py", line 504, in save
    f(self, obj) # Call unbound method with explicit self
[2022-08-18 05:50:25,101] {logging_mixin.py:115} WARNING -   File "/usr/local/lib/python3.7/pickle.py", line 789, in save_tuple
    save(element)
[2022-08-18 05:50:25,102] {logging_mixin.py:115} WARNING -   File "/usr/local/lib/python3.7/pickle.py", line 504, in save
    f(self, obj) # Call unbound method with explicit self
[2022-08-18 05:50:25,102] {logging_mixin.py:115} WARNING -   File "/home/***/.local/lib/python3.7/site-packages/pyspark/cloudpickle/cloudpickle_fast.py", line 784, in save_function
    *self._dynamic_function_reduce(obj), obj=obj
[2022-08-18 05:50:25,102] {logging_mixin.py:115} WARNING -   File "/home/***/.local/lib/python3.7/site-packages/pyspark/cloudpickle/cloudpickle_fast.py", line 721, in _save_reduce_pickle5
    dictitems=dictitems, obj=obj
[2022-08-18 05:50:25,103] {logging_mixin.py:115} WARNING -   File "/usr/local/lib/python3.7/pickle.py", line 638, in save_reduce
    save(args)
[2022-08-18 05:50:25,103] {logging_mixin.py:115} WARNING -   File "/usr/local/lib/python3.7/pickle.py", line 504, in save
    f(self, obj) # Call unbound method with explicit self
[2022-08-18 05:50:25,104] {logging_mixin.py:115} WARNING -   File "/usr/local/lib/python3.7/pickle.py", line 789, in save_tuple
    save(element)
[2022-08-18 05:50:25,104] {logging_mixin.py:115} WARNING -   File "/usr/local/lib/python3.7/pickle.py", line 504, in save
    f(self, obj) # Call unbound method with explicit self
[2022-08-18 05:50:25,105] {logging_mixin.py:115} WARNING -   File "/usr/local/lib/python3.7/pickle.py", line 774, in save_tuple
    save(element)
[2022-08-18 05:50:25,105] {logging_mixin.py:115} WARNING -   File "/usr/local/lib/python3.7/pickle.py", line 504, in save
    f(self, obj) # Call unbound method with explicit self
[2022-08-18 05:50:25,106] {logging_mixin.py:115} WARNING -   File "/home/***/.local/lib/python3.7/site-packages/dill/_dill.py", line 1146, in save_cell
    f = obj.cell_contents
[2022-08-18 05:50:25,106] {logging_mixin.py:115} WARNING - ValueError: Cell is empty
[2022-08-18 05:50:25,107] {taskinstance.py:1909} ERROR - Task failed with exception
Traceback (most recent call last):
  File "/home/airflow/.local/lib/python3.7/site-packages/pyspark/serializers.py", line 458, in dumps
    return cloudpickle.dumps(obj, pickle_protocol)
  File "/home/airflow/.local/lib/python3.7/site-packages/pyspark/cloudpickle/cloudpickle_fast.py", line 102, in dumps
    cp.dump(obj)
  File "/home/airflow/.local/lib/python3.7/site-packages/pyspark/cloudpickle/cloudpickle_fast.py", line 602, in dump
    return Pickler.dump(self, obj)
  File "/usr/local/lib/python3.7/pickle.py", line 437, in dump
    self.save(obj)
  File "/usr/local/lib/python3.7/pickle.py", line 504, in save
    f(self, obj) # Call unbound method with explicit self
  File "/usr/local/lib/python3.7/pickle.py", line 789, in save_tuple
    save(element)
  File "/usr/local/lib/python3.7/pickle.py", line 504, in save
    f(self, obj) # Call unbound method with explicit self
  File "/home/airflow/.local/lib/python3.7/site-packages/pyspark/cloudpickle/cloudpickle_fast.py", line 784, in save_function
    *self._dynamic_function_reduce(obj), obj=obj
  File "/home/airflow/.local/lib/python3.7/site-packages/pyspark/cloudpickle/cloudpickle_fast.py", line 721, in _save_reduce_pickle5
    dictitems=dictitems, obj=obj
  File "/usr/local/lib/python3.7/pickle.py", line 638, in save_reduce
    save(args)
  File "/usr/local/lib/python3.7/pickle.py", line 504, in save
    f(self, obj) # Call unbound method with explicit self
  File "/usr/local/lib/python3.7/pickle.py", line 789, in save_tuple
    save(element)
  File "/usr/local/lib/python3.7/pickle.py", line 504, in save
    f(self, obj) # Call unbound method with explicit self
  File "/usr/local/lib/python3.7/pickle.py", line 774, in save_tuple
    save(element)
  File "/usr/local/lib/python3.7/pickle.py", line 504, in save
    f(self, obj) # Call unbound method with explicit self
  File "/home/airflow/.local/lib/python3.7/site-packages/dill/_dill.py", line 1146, in save_cell
    f = obj.cell_contents
ValueError: Cell is empty

During handling of the above exception, another exception occurred:

Traceback (most recent call last):
  File "/home/airflow/.local/lib/python3.7/site-packages/airflow/operators/python.py", line 171, in execute
    return_value = self.execute_callable()
  File "/home/airflow/.local/lib/python3.7/site-packages/airflow/operators/python.py", line 189, in execute_callable
    return self.python_callable(*self.op_args, **self.op_kwargs)
  File "/opt/airflow/dags/newtest.py", line 123, in totaldb
    df=spark.createDataFrame(data=data, schema= dataColumns)
  File "/home/airflow/.local/lib/python3.7/site-packages/pyspark/sql/session.py", line 895, in createDataFrame
    data, schema, samplingRatio, verifySchema  # type: ignore[arg-type]
  File "/home/airflow/.local/lib/python3.7/site-packages/pyspark/sql/session.py", line 938, in _create_dataframe
    jrdd = self._jvm.SerDeUtil.toJavaArray(rdd._to_java_object_rdd())
  File "/home/airflow/.local/lib/python3.7/site-packages/pyspark/rdd.py", line 3113, in _to_java_object_rdd
    return self.ctx._jvm.SerDeUtil.pythonToJava(rdd._jrdd, True)
  File "/home/airflow/.local/lib/python3.7/site-packages/pyspark/rdd.py", line 3506, in _jrdd
    self.ctx, self.func, self._prev_jrdd_deserializer, self._jrdd_deserializer, profiler
  File "/home/airflow/.local/lib/python3.7/site-packages/pyspark/rdd.py", line 3362, in _wrap_function
    pickled_command, broadcast_vars, env, includes = _prepare_for_python_RDD(sc, command)
  File "/home/airflow/.local/lib/python3.7/site-packages/pyspark/rdd.py", line 3345, in _prepare_for_python_RDD
    pickled_command = ser.dumps(command)
  File "/home/airflow/.local/lib/python3.7/site-packages/pyspark/serializers.py", line 468, in dumps
    raise pickle.PicklingError(msg)
_pickle.PicklingError: Could not serialize object: ValueError: Cell is empty
[2022-08-18 05:50:25,128] {taskinstance.py:1420} INFO - Marking task as UP_FOR_RETRY. dag_id=craw, task_id=db, execution_date=20220818T043828, start_date=20220818T055007, end_date=20220818T055025
[2022-08-18 05:50:25,158] {standard_task_runner.py:97} ERROR - Failed to execute job 217 for task db (Could not serialize object: ValueError: Cell is empty; 2896)
[2022-08-18 05:50:25,191] {local_task_job.py:156} INFO - Task exited with return code 1
[2022-08-18 05:50:25,274] {local_task_job.py:273} INFO - 0 downstream tasks scheduled from follow-on schedule check
