[2022-08-18 04:24:35,798] {taskinstance.py:1179} INFO - Dependencies all met for <TaskInstance: craw.cr1 scheduled__2022-08-16T14:55:00+00:00 [queued]>
[2022-08-18 04:24:36,971] {taskinstance.py:1179} INFO - Dependencies all met for <TaskInstance: craw.cr1 scheduled__2022-08-16T14:55:00+00:00 [queued]>
[2022-08-18 04:24:36,996] {taskinstance.py:1376} INFO - 
--------------------------------------------------------------------------------
[2022-08-18 04:24:37,007] {taskinstance.py:1377} INFO - Starting attempt 1 of 2
[2022-08-18 04:24:37,010] {taskinstance.py:1378} INFO - 
--------------------------------------------------------------------------------
[2022-08-18 04:24:37,923] {taskinstance.py:1397} INFO - Executing <Task(PythonOperator): cr1> on 2022-08-16 14:55:00+00:00
[2022-08-18 04:24:40,597] {standard_task_runner.py:52} INFO - Started process 162 to run task
[2022-08-18 04:24:41,884] {standard_task_runner.py:79} INFO - Running: ['***', 'tasks', 'run', 'craw', 'cr1', 'scheduled__2022-08-16T14:55:00+00:00', '--job-id', '148', '--raw', '--subdir', 'DAGS_FOLDER/newtest.py', '--cfg-path', '/tmp/tmphiev4_ln', '--error-file', '/tmp/tmpq76i8fmo']
[2022-08-18 04:24:41,924] {standard_task_runner.py:80} INFO - Job 148: Subtask cr1
[2022-08-18 04:24:49,159] {task_command.py:371} INFO - Running <TaskInstance: craw.cr1 scheduled__2022-08-16T14:55:00+00:00 [running]> on host d59619969b18
[2022-08-18 04:24:55,440] {taskinstance.py:1591} INFO - Exporting the following env vars:
AIRFLOW_CTX_DAG_OWNER=***
AIRFLOW_CTX_DAG_ID=craw
AIRFLOW_CTX_TASK_ID=cr1
AIRFLOW_CTX_EXECUTION_DATE=2022-08-16T14:55:00+00:00
AIRFLOW_CTX_TRY_NUMBER=1
AIRFLOW_CTX_DAG_RUN_ID=scheduled__2022-08-16T14:55:00+00:00
[2022-08-18 04:26:57,545] {taskinstance.py:1909} ERROR - Task failed with exception
Traceback (most recent call last):
  File "/home/airflow/.local/lib/python3.7/site-packages/airflow/operators/python.py", line 171, in execute
    return_value = self.execute_callable()
  File "/home/airflow/.local/lib/python3.7/site-packages/airflow/operators/python.py", line 189, in execute_callable
    return self.python_callable(*self.op_args, **self.op_kwargs)
  File "/opt/airflow/dags/newtest.py", line 40, in crawling
    conn= mysql_hook.get_conn()
  File "/home/airflow/.local/lib/python3.7/site-packages/airflow/providers/mysql/hooks/mysql.py", line 158, in get_conn
    conn = self.connection or self.get_connection(getattr(self, self.conn_name_attr))
  File "/home/airflow/.local/lib/python3.7/site-packages/airflow/hooks/base.py", line 67, in get_connection
    conn = Connection.get_connection_from_secrets(conn_id)
  File "/home/airflow/.local/lib/python3.7/site-packages/airflow/models/connection.py", line 430, in get_connection_from_secrets
    raise AirflowNotFoundException(f"The conn_id `{conn_id}` isn't defined")
airflow.exceptions.AirflowNotFoundException: The conn_id `mysql` isn't defined
[2022-08-18 04:26:57,873] {taskinstance.py:1420} INFO - Marking task as UP_FOR_RETRY. dag_id=craw, task_id=cr1, execution_date=20220816T145500, start_date=20220818T042435, end_date=20220818T042657
[2022-08-18 04:26:57,967] {standard_task_runner.py:97} ERROR - Failed to execute job 148 for task cr1 (The conn_id `mysql` isn't defined; 162)
[2022-08-18 04:26:58,093] {local_task_job.py:156} INFO - Task exited with return code 1
[2022-08-18 04:26:58,654] {local_task_job.py:273} INFO - 0 downstream tasks scheduled from follow-on schedule check
[2022-08-18 04:26:58,963] {dagrun.py:1081} ERROR - Failed to get task '<TaskInstance: craw.con scheduled__2022-08-16T14:55:00+00:00 [removed]>' for dag 'craw'. Marking it as removed.
[2022-08-18 13:12:54,213] {taskinstance.py:1173} INFO - Dependencies not met for <TaskInstance: craw.cr1 scheduled__2022-08-16T14:55:00+00:00 [skipped]>, dependency 'Task Instance State' FAILED: Task is in the 'skipped' state.
[2022-08-18 13:12:54,233] {local_task_job.py:101} INFO - Task is not able to be run
