[2022-08-11 02:20:59,183] {taskinstance.py:1179} INFO - Dependencies all met for <TaskInstance: craw.cr1 manual__2022-08-11T02:20:56.258774+00:00 [queued]>
[2022-08-11 02:20:59,220] {taskinstance.py:1179} INFO - Dependencies all met for <TaskInstance: craw.cr1 manual__2022-08-11T02:20:56.258774+00:00 [queued]>
[2022-08-11 02:20:59,222] {taskinstance.py:1376} INFO - 
--------------------------------------------------------------------------------
[2022-08-11 02:20:59,222] {taskinstance.py:1377} INFO - Starting attempt 1 of 2
[2022-08-11 02:20:59,223] {taskinstance.py:1378} INFO - 
--------------------------------------------------------------------------------
[2022-08-11 02:20:59,318] {taskinstance.py:1397} INFO - Executing <Task(PythonOperator): cr1> on 2022-08-11 02:20:56.258774+00:00
[2022-08-11 02:20:59,339] {standard_task_runner.py:52} INFO - Started process 789 to run task
[2022-08-11 02:20:59,358] {standard_task_runner.py:79} INFO - Running: ['***', 'tasks', 'run', 'craw', 'cr1', 'manual__2022-08-11T02:20:56.258774+00:00', '--job-id', '49', '--raw', '--subdir', 'DAGS_FOLDER/newtest.py', '--cfg-path', '/tmp/tmpewldhusp', '--error-file', '/tmp/tmpu6vtpjsx']
[2022-08-11 02:20:59,376] {standard_task_runner.py:80} INFO - Job 49: Subtask cr1
[2022-08-11 02:20:59,596] {task_command.py:371} INFO - Running <TaskInstance: craw.cr1 manual__2022-08-11T02:20:56.258774+00:00 [running]> on host d59619969b18
[2022-08-11 02:21:00,023] {taskinstance.py:1591} INFO - Exporting the following env vars:
AIRFLOW_CTX_DAG_OWNER=***
AIRFLOW_CTX_DAG_ID=craw
AIRFLOW_CTX_TASK_ID=cr1
AIRFLOW_CTX_EXECUTION_DATE=2022-08-11T02:20:56.258774+00:00
AIRFLOW_CTX_TRY_NUMBER=1
AIRFLOW_CTX_DAG_RUN_ID=manual__2022-08-11T02:20:56.258774+00:00
[2022-08-11 02:21:00,136] {taskinstance.py:1909} ERROR - Task failed with exception
Traceback (most recent call last):
  File "/home/airflow/.local/lib/python3.7/site-packages/airflow/operators/python.py", line 171, in execute
    return_value = self.execute_callable()
  File "/home/airflow/.local/lib/python3.7/site-packages/airflow/operators/python.py", line 189, in execute_callable
    return self.python_callable(*self.op_args, **self.op_kwargs)
  File "/opt/airflow/dags/newtest.py", line 106, in craw1
    crawling(1,3,lists)
NameError: name 'lists' is not defined
[2022-08-11 02:21:03,658] {taskinstance.py:1420} INFO - Marking task as UP_FOR_RETRY. dag_id=craw, task_id=cr1, execution_date=20220811T022056, start_date=20220811T022059, end_date=20220811T022103
[2022-08-11 02:21:04,699] {standard_task_runner.py:97} ERROR - Failed to execute job 49 for task cr1 (name 'lists' is not defined; 789)
[2022-08-11 02:21:04,781] {local_task_job.py:156} INFO - Task exited with return code 1
[2022-08-11 02:21:04,928] {local_task_job.py:273} INFO - 0 downstream tasks scheduled from follow-on schedule check
