[2022-08-13 08:22:48,251] {taskinstance.py:1179} INFO - Dependencies all met for <TaskInstance: workflow.create_table manual__2022-08-13T08:22:45.365198+00:00 [queued]>
[2022-08-13 08:22:48,276] {taskinstance.py:1179} INFO - Dependencies all met for <TaskInstance: workflow.create_table manual__2022-08-13T08:22:45.365198+00:00 [queued]>
[2022-08-13 08:22:48,278] {taskinstance.py:1376} INFO - 
--------------------------------------------------------------------------------
[2022-08-13 08:22:48,279] {taskinstance.py:1377} INFO - Starting attempt 1 of 1
[2022-08-13 08:22:48,280] {taskinstance.py:1378} INFO - 
--------------------------------------------------------------------------------
[2022-08-13 08:22:48,328] {taskinstance.py:1397} INFO - Executing <Task(MySqlOperator): create_table> on 2022-08-13 08:22:45.365198+00:00
[2022-08-13 08:22:48,339] {standard_task_runner.py:52} INFO - Started process 340 to run task
[2022-08-13 08:22:48,350] {standard_task_runner.py:79} INFO - Running: ['***', 'tasks', 'run', 'workflow', 'create_table', 'manual__2022-08-13T08:22:45.365198+00:00', '--job-id', '30', '--raw', '--subdir', 'DAGS_FOLDER/test.py', '--cfg-path', '/tmp/tmpdla_re0j', '--error-file', '/tmp/tmpayneyttv']
[2022-08-13 08:22:48,351] {standard_task_runner.py:80} INFO - Job 30: Subtask create_table
[2022-08-13 08:22:48,571] {task_command.py:371} INFO - Running <TaskInstance: workflow.create_table manual__2022-08-13T08:22:45.365198+00:00 [running]> on host cdb6935da655
[2022-08-13 08:22:48,852] {taskinstance.py:1591} INFO - Exporting the following env vars:
AIRFLOW_CTX_DAG_OWNER=***
AIRFLOW_CTX_DAG_ID=workflow
AIRFLOW_CTX_TASK_ID=create_table
AIRFLOW_CTX_EXECUTION_DATE=2022-08-13T08:22:45.365198+00:00
AIRFLOW_CTX_TRY_NUMBER=1
AIRFLOW_CTX_DAG_RUN_ID=manual__2022-08-13T08:22:45.365198+00:00
[2022-08-13 08:22:48,854] {mysql.py:82} INFO - Executing: CREATE DATABASE qweql
[2022-08-13 08:22:48,920] {taskinstance.py:1909} ERROR - Task failed with exception
Traceback (most recent call last):
  File "/home/airflow/.local/lib/python3.7/site-packages/airflow/providers/mysql/operators/mysql.py", line 84, in execute
    hook.run(self.sql, autocommit=self.autocommit, parameters=self.parameters)
  File "/home/airflow/.local/lib/python3.7/site-packages/airflow/hooks/dbapi.py", line 204, in run
    with closing(self.get_conn()) as conn:
  File "/home/airflow/.local/lib/python3.7/site-packages/airflow/providers/mysql/hooks/mysql.py", line 158, in get_conn
    conn = self.connection or self.get_connection(getattr(self, self.conn_name_attr))
  File "/home/airflow/.local/lib/python3.7/site-packages/airflow/hooks/base.py", line 67, in get_connection
    conn = Connection.get_connection_from_secrets(conn_id)
  File "/home/airflow/.local/lib/python3.7/site-packages/airflow/models/connection.py", line 430, in get_connection_from_secrets
    raise AirflowNotFoundException(f"The conn_id `{conn_id}` isn't defined")
airflow.exceptions.AirflowNotFoundException: The conn_id `mysql_db` isn't defined
[2022-08-13 08:22:48,932] {taskinstance.py:1420} INFO - Marking task as FAILED. dag_id=workflow, task_id=create_table, execution_date=20220813T082245, start_date=20220813T082248, end_date=20220813T082248
[2022-08-13 08:22:48,960] {standard_task_runner.py:97} ERROR - Failed to execute job 30 for task create_table (The conn_id `mysql_db` isn't defined; 340)
[2022-08-13 08:22:49,012] {local_task_job.py:156} INFO - Task exited with return code 1
[2022-08-13 08:22:49,073] {local_task_job.py:273} INFO - 0 downstream tasks scheduled from follow-on schedule check
