[2022-08-18 04:24:31,344] {taskinstance.py:1179} INFO - Dependencies all met for <TaskInstance: craw.cr2 scheduled__2022-08-13T14:55:00+00:00 [queued]>
[2022-08-18 04:24:31,639] {taskinstance.py:1179} INFO - Dependencies all met for <TaskInstance: craw.cr2 scheduled__2022-08-13T14:55:00+00:00 [queued]>
[2022-08-18 04:24:31,643] {taskinstance.py:1376} INFO - 
--------------------------------------------------------------------------------
[2022-08-18 04:24:31,644] {taskinstance.py:1377} INFO - Starting attempt 2 of 2
[2022-08-18 04:24:31,645] {taskinstance.py:1378} INFO - 
--------------------------------------------------------------------------------
[2022-08-18 04:24:34,081] {taskinstance.py:1397} INFO - Executing <Task(PythonOperator): cr2> on 2022-08-13 14:55:00+00:00
[2022-08-18 04:24:35,490] {standard_task_runner.py:52} INFO - Started process 160 to run task
[2022-08-18 04:24:36,221] {standard_task_runner.py:79} INFO - Running: ['***', 'tasks', 'run', 'craw', 'cr2', 'scheduled__2022-08-13T14:55:00+00:00', '--job-id', '147', '--raw', '--subdir', 'DAGS_FOLDER/newtest.py', '--cfg-path', '/tmp/tmph3yg3i7e', '--error-file', '/tmp/tmp8fjg4215']
[2022-08-18 04:24:36,323] {standard_task_runner.py:80} INFO - Job 147: Subtask cr2
[2022-08-18 04:24:42,392] {task_command.py:371} INFO - Running <TaskInstance: craw.cr2 scheduled__2022-08-13T14:55:00+00:00 [running]> on host d59619969b18
[2022-08-18 04:25:00,109] {taskinstance.py:1591} INFO - Exporting the following env vars:
AIRFLOW_CTX_DAG_OWNER=***
AIRFLOW_CTX_DAG_ID=craw
AIRFLOW_CTX_TASK_ID=cr2
AIRFLOW_CTX_EXECUTION_DATE=2022-08-13T14:55:00+00:00
AIRFLOW_CTX_TRY_NUMBER=2
AIRFLOW_CTX_DAG_RUN_ID=scheduled__2022-08-13T14:55:00+00:00
[2022-08-18 04:26:55,730] {taskinstance.py:1909} ERROR - Task failed with exception
Traceback (most recent call last):
  File "/home/airflow/.local/lib/python3.7/site-packages/airflow/operators/python.py", line 171, in execute
    return_value = self.execute_callable()
  File "/home/airflow/.local/lib/python3.7/site-packages/airflow/operators/python.py", line 189, in execute_callable
    return self.python_callable(*self.op_args, **self.op_kwargs)
  File "/opt/airflow/dags/newtest.py", line 40, in crawling
    conn= mysql_hook.get_conn()
  File "/home/airflow/.local/lib/python3.7/site-packages/airflow/providers/mysql/hooks/mysql.py", line 158, in get_conn
    conn = self.connection or self.get_connection(getattr(self, self.conn_name_attr))
  File "/home/airflow/.local/lib/python3.7/site-packages/airflow/hooks/base.py", line 67, in get_connection
    conn = Connection.get_connection_from_secrets(conn_id)
  File "/home/airflow/.local/lib/python3.7/site-packages/airflow/models/connection.py", line 430, in get_connection_from_secrets
    raise AirflowNotFoundException(f"The conn_id `{conn_id}` isn't defined")
airflow.exceptions.AirflowNotFoundException: The conn_id `mysql` isn't defined
[2022-08-18 04:26:55,849] {taskinstance.py:1420} INFO - Marking task as FAILED. dag_id=craw, task_id=cr2, execution_date=20220813T145500, start_date=20220818T042431, end_date=20220818T042655
[2022-08-18 04:26:56,029] {standard_task_runner.py:97} ERROR - Failed to execute job 147 for task cr2 (The conn_id `mysql` isn't defined; 160)
[2022-08-18 04:26:56,253] {local_task_job.py:156} INFO - Task exited with return code 1
[2022-08-18 04:26:56,784] {local_task_job.py:273} INFO - 0 downstream tasks scheduled from follow-on schedule check
[2022-08-18 04:26:56,941] {dagrun.py:1081} ERROR - Failed to get task '<TaskInstance: craw.con scheduled__2022-08-13T14:55:00+00:00 [removed]>' for dag 'craw'. Marking it as removed.
