[2022-08-19 03:27:28,458] {taskinstance.py:1179} INFO - Dependencies all met for <TaskInstance: craw.cr6 scheduled__2022-08-17T14:55:00+00:00 [queued]>
[2022-08-19 03:27:28,476] {taskinstance.py:1179} INFO - Dependencies all met for <TaskInstance: craw.cr6 scheduled__2022-08-17T14:55:00+00:00 [queued]>
[2022-08-19 03:27:28,477] {taskinstance.py:1376} INFO - 
--------------------------------------------------------------------------------
[2022-08-19 03:27:28,477] {taskinstance.py:1377} INFO - Starting attempt 2 of 2
[2022-08-19 03:27:28,478] {taskinstance.py:1378} INFO - 
--------------------------------------------------------------------------------
[2022-08-19 03:27:28,504] {taskinstance.py:1397} INFO - Executing <Task(PythonOperator): cr6> on 2022-08-17 14:55:00+00:00
[2022-08-19 03:27:28,513] {standard_task_runner.py:52} INFO - Started process 518 to run task
[2022-08-19 03:27:28,516] {standard_task_runner.py:79} INFO - Running: ['***', 'tasks', 'run', 'craw', 'cr6', 'scheduled__2022-08-17T14:55:00+00:00', '--job-id', '183', '--raw', '--subdir', 'DAGS_FOLDER/newtest.py', '--cfg-path', '/tmp/tmp5s9k_eni', '--error-file', '/tmp/tmpzxgwz5el']
[2022-08-19 03:27:28,518] {standard_task_runner.py:80} INFO - Job 183: Subtask cr6
[2022-08-19 03:27:28,613] {task_command.py:371} INFO - Running <TaskInstance: craw.cr6 scheduled__2022-08-17T14:55:00+00:00 [running]> on host 61280f7b642f
[2022-08-19 03:27:28,759] {taskinstance.py:1591} INFO - Exporting the following env vars:
AIRFLOW_CTX_DAG_OWNER=***
AIRFLOW_CTX_DAG_ID=craw
AIRFLOW_CTX_TASK_ID=cr6
AIRFLOW_CTX_EXECUTION_DATE=2022-08-17T14:55:00+00:00
AIRFLOW_CTX_TRY_NUMBER=2
AIRFLOW_CTX_DAG_RUN_ID=scheduled__2022-08-17T14:55:00+00:00
[2022-08-19 03:27:28,779] {base.py:68} INFO - Using connection ID 'mysql' for task execution.
[2022-08-19 03:27:38,792] {taskinstance.py:1909} ERROR - Task failed with exception
Traceback (most recent call last):
  File "/home/airflow/.local/lib/python3.7/site-packages/pymysql/connections.py", line 614, in connect
    (self.host, self.port), self.connect_timeout, **kwargs
  File "/usr/local/lib/python3.7/socket.py", line 707, in create_connection
    for res in getaddrinfo(host, port, 0, SOCK_STREAM):
  File "/usr/local/lib/python3.7/socket.py", line 752, in getaddrinfo
    for res in _socket.getaddrinfo(host, port, family, type, proto, flags):
socket.gaierror: [Errno -3] Temporary failure in name resolution

During handling of the above exception, another exception occurred:

Traceback (most recent call last):
  File "/home/airflow/.local/lib/python3.7/site-packages/airflow/operators/python.py", line 171, in execute
    return_value = self.execute_callable()
  File "/home/airflow/.local/lib/python3.7/site-packages/airflow/operators/python.py", line 189, in execute_callable
    return self.python_callable(*self.op_args, **self.op_kwargs)
  File "/opt/airflow/dags/newtest.py", line 39, in crawling
    conn= mysql_hook.get_conn()
  File "/home/airflow/.local/lib/python3.7/site-packages/airflow/providers/mysql/hooks/mysql.py", line 166, in get_conn
    return MySQLdb.connect(**conn_config)
  File "/home/airflow/.local/lib/python3.7/site-packages/pymysql/connections.py", line 353, in __init__
    self.connect()
  File "/home/airflow/.local/lib/python3.7/site-packages/pymysql/connections.py", line 664, in connect
    raise exc
pymysql.err.OperationalError: (2003, "Can't connect to MySQL server on 'mysql' ([Errno -3] Temporary failure in name resolution)")
[2022-08-19 03:27:38,811] {taskinstance.py:1420} INFO - Marking task as FAILED. dag_id=craw, task_id=cr6, execution_date=20220817T145500, start_date=20220819T032728, end_date=20220819T032738
[2022-08-19 03:27:39,036] {standard_task_runner.py:97} ERROR - Failed to execute job 183 for task cr6 ((2003, "Can't connect to MySQL server on 'mysql' ([Errno -3] Temporary failure in name resolution)"); 518)
[2022-08-19 03:27:39,059] {local_task_job.py:156} INFO - Task exited with return code 1
[2022-08-19 03:27:39,530] {local_task_job.py:273} INFO - 0 downstream tasks scheduled from follow-on schedule check
