[2022-08-13 09:08:33,233] {taskinstance.py:1179} INFO - Dependencies all met for <TaskInstance: craw.cr2 manual__2022-08-13T09:08:29.251869+00:00 [queued]>
[2022-08-13 09:08:33,245] {taskinstance.py:1179} INFO - Dependencies all met for <TaskInstance: craw.cr2 manual__2022-08-13T09:08:29.251869+00:00 [queued]>
[2022-08-13 09:08:33,245] {taskinstance.py:1376} INFO - 
--------------------------------------------------------------------------------
[2022-08-13 09:08:33,246] {taskinstance.py:1377} INFO - Starting attempt 1 of 2
[2022-08-13 09:08:33,246] {taskinstance.py:1378} INFO - 
--------------------------------------------------------------------------------
[2022-08-13 09:08:33,267] {taskinstance.py:1397} INFO - Executing <Task(PythonOperator): cr2> on 2022-08-13 09:08:29.251869+00:00
[2022-08-13 09:08:33,271] {standard_task_runner.py:52} INFO - Started process 4928 to run task
[2022-08-13 09:08:33,277] {standard_task_runner.py:79} INFO - Running: ['***', 'tasks', 'run', 'craw', 'cr2', 'manual__2022-08-13T09:08:29.251869+00:00', '--job-id', '57', '--raw', '--subdir', 'DAGS_FOLDER/newtest.py', '--cfg-path', '/tmp/tmptm222gec', '--error-file', '/tmp/tmpclee0y0l']
[2022-08-13 09:08:33,279] {standard_task_runner.py:80} INFO - Job 57: Subtask cr2
[2022-08-13 09:08:34,500] {task_command.py:371} INFO - Running <TaskInstance: craw.cr2 manual__2022-08-13T09:08:29.251869+00:00 [running]> on host cdb6935da655
[2022-08-13 09:08:35,554] {taskinstance.py:1591} INFO - Exporting the following env vars:
AIRFLOW_CTX_DAG_OWNER=***
AIRFLOW_CTX_DAG_ID=craw
AIRFLOW_CTX_TASK_ID=cr2
AIRFLOW_CTX_EXECUTION_DATE=2022-08-13T09:08:29.251869+00:00
AIRFLOW_CTX_TRY_NUMBER=1
AIRFLOW_CTX_DAG_RUN_ID=manual__2022-08-13T09:08:29.251869+00:00
[2022-08-13 09:08:35,563] {logger.py:11} INFO - ====== WebDriver manager ======
[2022-08-13 09:08:35,979] {logger.py:11} INFO - Get LATEST chromedriver version for google-chrome 104.0.5112
[2022-08-13 09:08:38,520] {logger.py:11} INFO - Driver [/home/***/.wdm/drivers/chromedriver/linux64/104.0.5112/chromedriver] found in cache
[2022-08-13 09:09:33,678] {base.py:68} INFO - Using connection ID 'mysql' for task execution.
[2022-08-13 09:09:33,686] {dbapi.py:231} INFO - Running statement: INSERT INTO info (image,name,price,review) VALUES (%s, %s, %s, %s), parameters: None
[2022-08-13 09:09:33,688] {taskinstance.py:1909} ERROR - Task failed with exception
Traceback (most recent call last):
  File "/home/airflow/.local/lib/python3.7/site-packages/airflow/operators/python.py", line 171, in execute
    return_value = self.execute_callable()
  File "/home/airflow/.local/lib/python3.7/site-packages/airflow/operators/python.py", line 189, in execute_callable
    return self.python_callable(*self.op_args, **self.op_kwargs)
  File "/opt/airflow/dags/newtest.py", line 94, in crawling
    mysql_hook.run(insert_mysql,(image,name,price,review))
  File "/home/airflow/.local/lib/python3.7/site-packages/airflow/hooks/dbapi.py", line 211, in run
    self._run_command(cur, sql_statement, parameters)
  File "/home/airflow/.local/lib/python3.7/site-packages/airflow/hooks/dbapi.py", line 235, in _run_command
    cur.execute(sql_statement)
  File "/home/airflow/.local/lib/python3.7/site-packages/pymysql/cursors.py", line 148, in execute
    result = self._query(query)
  File "/home/airflow/.local/lib/python3.7/site-packages/pymysql/cursors.py", line 310, in _query
    conn.query(q)
  File "/home/airflow/.local/lib/python3.7/site-packages/pymysql/connections.py", line 548, in query
    self._affected_rows = self._read_query_result(unbuffered=unbuffered)
  File "/home/airflow/.local/lib/python3.7/site-packages/pymysql/connections.py", line 775, in _read_query_result
    result.read()
  File "/home/airflow/.local/lib/python3.7/site-packages/pymysql/connections.py", line 1156, in read
    first_packet = self.connection._read_packet()
  File "/home/airflow/.local/lib/python3.7/site-packages/pymysql/connections.py", line 725, in _read_packet
    packet.raise_for_error()
  File "/home/airflow/.local/lib/python3.7/site-packages/pymysql/protocol.py", line 221, in raise_for_error
    err.raise_mysql_exception(self._data)
  File "/home/airflow/.local/lib/python3.7/site-packages/pymysql/err.py", line 143, in raise_mysql_exception
    raise errorclass(errno, errval)
pymysql.err.ProgrammingError: (1064, "You have an error in your SQL syntax; check the manual that corresponds to your MySQL server version for the right syntax to use near '%s, %s, %s, %s)' at line 1")
[2022-08-13 09:09:33,714] {taskinstance.py:1420} INFO - Marking task as UP_FOR_RETRY. dag_id=craw, task_id=cr2, execution_date=20220813T090829, start_date=20220813T090833, end_date=20220813T090933
[2022-08-13 09:09:33,867] {standard_task_runner.py:97} ERROR - Failed to execute job 57 for task cr2 ((1064, "You have an error in your SQL syntax; check the manual that corresponds to your MySQL server version for the right syntax to use near '%s, %s, %s, %s)' at line 1"); 4928)
[2022-08-13 09:09:33,933] {local_task_job.py:156} INFO - Task exited with return code 1
[2022-08-13 09:09:34,498] {local_task_job.py:273} INFO - 0 downstream tasks scheduled from follow-on schedule check
