[2022-08-12 07:28:13,507] {taskinstance.py:1179} INFO - Dependencies all met for <TaskInstance: craw.cr2 manual__2022-08-12T07:28:06.799989+00:00 [queued]>
[2022-08-12 07:28:13,540] {taskinstance.py:1179} INFO - Dependencies all met for <TaskInstance: craw.cr2 manual__2022-08-12T07:28:06.799989+00:00 [queued]>
[2022-08-12 07:28:13,541] {taskinstance.py:1376} INFO - 
--------------------------------------------------------------------------------
[2022-08-12 07:28:13,542] {taskinstance.py:1377} INFO - Starting attempt 1 of 2
[2022-08-12 07:28:13,543] {taskinstance.py:1378} INFO - 
--------------------------------------------------------------------------------
[2022-08-12 07:28:13,603] {taskinstance.py:1397} INFO - Executing <Task(PythonOperator): cr2> on 2022-08-12 07:28:06.799989+00:00
[2022-08-12 07:28:13,628] {standard_task_runner.py:52} INFO - Started process 290 to run task
[2022-08-12 07:28:13,649] {standard_task_runner.py:79} INFO - Running: ['***', 'tasks', 'run', 'craw', 'cr2', 'manual__2022-08-12T07:28:06.799989+00:00', '--job-id', '110', '--raw', '--subdir', 'DAGS_FOLDER/newtest.py', '--cfg-path', '/tmp/tmpvjwa4qlx', '--error-file', '/tmp/tmpgk34w44w']
[2022-08-12 07:28:13,663] {standard_task_runner.py:80} INFO - Job 110: Subtask cr2
[2022-08-12 07:28:14,297] {task_command.py:371} INFO - Running <TaskInstance: craw.cr2 manual__2022-08-12T07:28:06.799989+00:00 [running]> on host d59619969b18
[2022-08-12 07:28:16,133] {taskinstance.py:1591} INFO - Exporting the following env vars:
AIRFLOW_CTX_DAG_OWNER=***
AIRFLOW_CTX_DAG_ID=craw
AIRFLOW_CTX_TASK_ID=cr2
AIRFLOW_CTX_EXECUTION_DATE=2022-08-12T07:28:06.799989+00:00
AIRFLOW_CTX_TRY_NUMBER=1
AIRFLOW_CTX_DAG_RUN_ID=manual__2022-08-12T07:28:06.799989+00:00
[2022-08-12 07:28:16,194] {taskinstance.py:1909} ERROR - Task failed with exception
Traceback (most recent call last):
  File "/home/airflow/.local/lib/python3.7/site-packages/pymysql/connections.py", line 614, in connect
    (self.host, self.port), self.connect_timeout, **kwargs
  File "/usr/local/lib/python3.7/socket.py", line 728, in create_connection
    raise err
  File "/usr/local/lib/python3.7/socket.py", line 716, in create_connection
    sock.connect(sa)
ConnectionRefusedError: [Errno 111] Connection refused

During handling of the above exception, another exception occurred:

Traceback (most recent call last):
  File "/home/airflow/.local/lib/python3.7/site-packages/airflow/operators/python.py", line 171, in execute
    return_value = self.execute_callable()
  File "/home/airflow/.local/lib/python3.7/site-packages/airflow/operators/python.py", line 189, in execute_callable
    return self.python_callable(*self.op_args, **self.op_kwargs)
  File "/opt/airflow/dags/newtest.py", line 41, in crawling
    charset='utf8')
  File "/home/airflow/.local/lib/python3.7/site-packages/pymysql/connections.py", line 353, in __init__
    self.connect()
  File "/home/airflow/.local/lib/python3.7/site-packages/pymysql/connections.py", line 664, in connect
    raise exc
pymysql.err.OperationalError: (2003, "Can't connect to MySQL server on '127.0.0.1' ([Errno 111] Connection refused)")
[2022-08-12 07:28:16,278] {taskinstance.py:1420} INFO - Marking task as UP_FOR_RETRY. dag_id=craw, task_id=cr2, execution_date=20220812T072806, start_date=20220812T072813, end_date=20220812T072816
[2022-08-12 07:28:16,352] {standard_task_runner.py:97} ERROR - Failed to execute job 110 for task cr2 ((2003, "Can't connect to MySQL server on '127.0.0.1' ([Errno 111] Connection refused)"); 290)
[2022-08-12 07:28:16,414] {local_task_job.py:156} INFO - Task exited with return code 1
[2022-08-12 07:28:16,541] {local_task_job.py:273} INFO - 0 downstream tasks scheduled from follow-on schedule check
