[2022-08-20 16:47:35,916] {taskinstance.py:1179} INFO - Dependencies all met for <TaskInstance: craw.cr2 scheduled__2022-08-19T14:55:00+00:00 [queued]>
[2022-08-20 16:47:35,931] {taskinstance.py:1179} INFO - Dependencies all met for <TaskInstance: craw.cr2 scheduled__2022-08-19T14:55:00+00:00 [queued]>
[2022-08-20 16:47:35,932] {taskinstance.py:1376} INFO - 
--------------------------------------------------------------------------------
[2022-08-20 16:47:35,936] {taskinstance.py:1377} INFO - Starting attempt 2 of 2
[2022-08-20 16:47:35,937] {taskinstance.py:1378} INFO - 
--------------------------------------------------------------------------------
[2022-08-20 16:47:35,953] {taskinstance.py:1397} INFO - Executing <Task(PythonOperator): cr2> on 2022-08-19 14:55:00+00:00
[2022-08-20 16:47:35,960] {standard_task_runner.py:52} INFO - Started process 298 to run task
[2022-08-20 16:47:35,966] {standard_task_runner.py:79} INFO - Running: ['***', 'tasks', 'run', 'craw', 'cr2', 'scheduled__2022-08-19T14:55:00+00:00', '--job-id', '156', '--raw', '--subdir', 'DAGS_FOLDER/newtest.py', '--cfg-path', '/tmp/tmp53yao8eu', '--error-file', '/tmp/tmpomc5ff8y']
[2022-08-20 16:47:35,972] {standard_task_runner.py:80} INFO - Job 156: Subtask cr2
[2022-08-20 16:47:36,074] {task_command.py:371} INFO - Running <TaskInstance: craw.cr2 scheduled__2022-08-19T14:55:00+00:00 [running]> on host 0d2dcb932a96
[2022-08-20 16:47:36,191] {taskinstance.py:1589} INFO - Exporting the following env vars:
AIRFLOW_CTX_DAG_OWNER=***
AIRFLOW_CTX_DAG_ID=craw
AIRFLOW_CTX_TASK_ID=cr2
AIRFLOW_CTX_EXECUTION_DATE=2022-08-19T14:55:00+00:00
AIRFLOW_CTX_TRY_NUMBER=2
AIRFLOW_CTX_DAG_RUN_ID=scheduled__2022-08-19T14:55:00+00:00
[2022-08-20 16:47:36,215] {base.py:68} INFO - Using connection ID 'mysql' for task execution.
[2022-08-20 16:47:46,224] {taskinstance.py:1909} ERROR - Task failed with exception
Traceback (most recent call last):
  File "/home/airflow/.local/lib/python3.8/site-packages/pymysql/connections.py", line 613, in connect
    sock = socket.create_connection(
  File "/usr/local/lib/python3.8/socket.py", line 787, in create_connection
    for res in getaddrinfo(host, port, 0, SOCK_STREAM):
  File "/usr/local/lib/python3.8/socket.py", line 918, in getaddrinfo
    for res in _socket.getaddrinfo(host, port, family, type, proto, flags):
socket.gaierror: [Errno -3] Temporary failure in name resolution

During handling of the above exception, another exception occurred:

Traceback (most recent call last):
  File "/home/airflow/.local/lib/python3.8/site-packages/airflow/operators/python.py", line 171, in execute
    return_value = self.execute_callable()
  File "/home/airflow/.local/lib/python3.8/site-packages/airflow/operators/python.py", line 189, in execute_callable
    return self.python_callable(*self.op_args, **self.op_kwargs)
  File "/opt/airflow/dags/newtest.py", line 39, in crawling
    conn= mysql_hook.get_conn()
  File "/home/airflow/.local/lib/python3.8/site-packages/airflow/providers/mysql/hooks/mysql.py", line 166, in get_conn
    return MySQLdb.connect(**conn_config)
  File "/home/airflow/.local/lib/python3.8/site-packages/pymysql/connections.py", line 353, in __init__
    self.connect()
  File "/home/airflow/.local/lib/python3.8/site-packages/pymysql/connections.py", line 664, in connect
    raise exc
pymysql.err.OperationalError: (2003, "Can't connect to MySQL server on 'mysql' ([Errno -3] Temporary failure in name resolution)")
[2022-08-20 16:47:46,250] {taskinstance.py:1415} INFO - Marking task as FAILED. dag_id=craw, task_id=cr2, execution_date=20220819T145500, start_date=20220820T164735, end_date=20220820T164746
[2022-08-20 16:47:46,272] {standard_task_runner.py:92} ERROR - Failed to execute job 156 for task cr2 ((2003, "Can't connect to MySQL server on 'mysql' ([Errno -3] Temporary failure in name resolution)"); 298)
[2022-08-20 16:47:46,293] {local_task_job.py:156} INFO - Task exited with return code 1
[2022-08-20 16:47:46,327] {local_task_job.py:273} INFO - 0 downstream tasks scheduled from follow-on schedule check
