[2022-08-18 04:23:54,853] {taskinstance.py:1179} INFO - Dependencies all met for <TaskInstance: craw.cr1 scheduled__2022-08-13T14:55:00+00:00 [queued]>
[2022-08-18 04:24:00,719] {taskinstance.py:1179} INFO - Dependencies all met for <TaskInstance: craw.cr1 scheduled__2022-08-13T14:55:00+00:00 [queued]>
[2022-08-18 04:24:00,765] {taskinstance.py:1376} INFO - 
--------------------------------------------------------------------------------
[2022-08-18 04:24:01,049] {taskinstance.py:1377} INFO - Starting attempt 2 of 2
[2022-08-18 04:24:01,133] {taskinstance.py:1378} INFO - 
--------------------------------------------------------------------------------
[2022-08-18 04:24:09,761] {taskinstance.py:1397} INFO - Executing <Task(PythonOperator): cr1> on 2022-08-13 14:55:00+00:00
[2022-08-18 04:24:10,889] {standard_task_runner.py:52} INFO - Started process 144 to run task
[2022-08-18 04:24:15,465] {standard_task_runner.py:79} INFO - Running: ['***', 'tasks', 'run', 'craw', 'cr1', 'scheduled__2022-08-13T14:55:00+00:00', '--job-id', '143', '--raw', '--subdir', 'DAGS_FOLDER/newtest.py', '--cfg-path', '/tmp/tmp44ntqmhd', '--error-file', '/tmp/tmpbcso4u0j']
[2022-08-18 04:24:15,803] {standard_task_runner.py:80} INFO - Job 143: Subtask cr1
[2022-08-18 04:24:32,188] {task_command.py:371} INFO - Running <TaskInstance: craw.cr1 scheduled__2022-08-13T14:55:00+00:00 [running]> on host d59619969b18
[2022-08-18 04:24:39,127] {taskinstance.py:1591} INFO - Exporting the following env vars:
AIRFLOW_CTX_DAG_OWNER=***
AIRFLOW_CTX_DAG_ID=craw
AIRFLOW_CTX_TASK_ID=cr1
AIRFLOW_CTX_EXECUTION_DATE=2022-08-13T14:55:00+00:00
AIRFLOW_CTX_TRY_NUMBER=2
AIRFLOW_CTX_DAG_RUN_ID=scheduled__2022-08-13T14:55:00+00:00
[2022-08-18 04:26:59,950] {taskinstance.py:1909} ERROR - Task failed with exception
Traceback (most recent call last):
  File "/home/airflow/.local/lib/python3.7/site-packages/airflow/operators/python.py", line 171, in execute
    return_value = self.execute_callable()
  File "/home/airflow/.local/lib/python3.7/site-packages/airflow/operators/python.py", line 189, in execute_callable
    return self.python_callable(*self.op_args, **self.op_kwargs)
  File "/opt/airflow/dags/newtest.py", line 40, in crawling
    conn= mysql_hook.get_conn()
  File "/home/airflow/.local/lib/python3.7/site-packages/airflow/providers/mysql/hooks/mysql.py", line 158, in get_conn
    conn = self.connection or self.get_connection(getattr(self, self.conn_name_attr))
  File "/home/airflow/.local/lib/python3.7/site-packages/airflow/hooks/base.py", line 67, in get_connection
    conn = Connection.get_connection_from_secrets(conn_id)
  File "/home/airflow/.local/lib/python3.7/site-packages/airflow/models/connection.py", line 430, in get_connection_from_secrets
    raise AirflowNotFoundException(f"The conn_id `{conn_id}` isn't defined")
airflow.exceptions.AirflowNotFoundException: The conn_id `mysql` isn't defined
[2022-08-18 04:27:00,113] {taskinstance.py:1420} INFO - Marking task as FAILED. dag_id=craw, task_id=cr1, execution_date=20220813T145500, start_date=20220818T042358, end_date=20220818T042700
[2022-08-18 04:27:00,335] {standard_task_runner.py:97} ERROR - Failed to execute job 143 for task cr1 (The conn_id `mysql` isn't defined; 144)
[2022-08-18 04:27:00,497] {local_task_job.py:156} INFO - Task exited with return code 1
[2022-08-18 04:27:01,173] {local_task_job.py:273} INFO - 0 downstream tasks scheduled from follow-on schedule check
[2022-08-18 04:27:01,323] {dagrun.py:1081} ERROR - Failed to get task '<TaskInstance: craw.con scheduled__2022-08-13T14:55:00+00:00 [removed]>' for dag 'craw'. Marking it as removed.
[2022-08-18 04:27:01,377] {dagrun.py:549} ERROR - Marking run <DagRun craw @ 2022-08-13 14:55:00+00:00: scheduled__2022-08-13T14:55:00+00:00, externally triggered: False> failed
[2022-08-18 04:27:01,440] {dagrun.py:624} INFO - DagRun Finished: dag_id=craw, execution_date=2022-08-13 14:55:00+00:00, run_id=scheduled__2022-08-13T14:55:00+00:00, run_start_date=2022-08-15 23:39:03.433400+00:00, run_end_date=2022-08-18 04:27:01.439420+00:00, run_duration=190078.00602, state=failed, external_trigger=False, run_type=scheduled, data_interval_start=2022-08-13 14:55:00+00:00, data_interval_end=2022-08-14 14:55:00+00:00, dag_hash=fd45af906d5737517baceb20b8f123ca
