[2022-08-11 23:33:24,793] {taskinstance.py:1179} INFO - Dependencies all met for <TaskInstance: craw.result scheduled__2022-08-10T14:55:00+00:00 [queued]>
[2022-08-11 23:33:24,831] {taskinstance.py:1179} INFO - Dependencies all met for <TaskInstance: craw.result scheduled__2022-08-10T14:55:00+00:00 [queued]>
[2022-08-11 23:33:24,832] {taskinstance.py:1376} INFO - 
--------------------------------------------------------------------------------
[2022-08-11 23:33:24,833] {taskinstance.py:1377} INFO - Starting attempt 1 of 2
[2022-08-11 23:33:24,834] {taskinstance.py:1378} INFO - 
--------------------------------------------------------------------------------
[2022-08-11 23:33:24,912] {taskinstance.py:1397} INFO - Executing <Task(PythonOperator): result> on 2022-08-10 14:55:00+00:00
[2022-08-11 23:33:24,924] {standard_task_runner.py:52} INFO - Started process 29349 to run task
[2022-08-11 23:33:24,935] {standard_task_runner.py:79} INFO - Running: ['***', 'tasks', 'run', 'craw', 'result', 'scheduled__2022-08-10T14:55:00+00:00', '--job-id', '89', '--raw', '--subdir', 'DAGS_FOLDER/newtest.py', '--cfg-path', '/tmp/tmp0a_l1wma', '--error-file', '/tmp/tmpp34fy3_o']
[2022-08-11 23:33:24,940] {standard_task_runner.py:80} INFO - Job 89: Subtask result
[2022-08-11 23:33:25,420] {task_command.py:371} INFO - Running <TaskInstance: craw.result scheduled__2022-08-10T14:55:00+00:00 [running]> on host d59619969b18
[2022-08-11 23:33:27,706] {taskinstance.py:1591} INFO - Exporting the following env vars:
AIRFLOW_CTX_DAG_OWNER=***
AIRFLOW_CTX_DAG_ID=craw
AIRFLOW_CTX_TASK_ID=result
AIRFLOW_CTX_EXECUTION_DATE=2022-08-10T14:55:00+00:00
AIRFLOW_CTX_TRY_NUMBER=1
AIRFLOW_CTX_DAG_RUN_ID=scheduled__2022-08-10T14:55:00+00:00
[2022-08-11 23:33:27,768] {taskinstance.py:1909} ERROR - Task failed with exception
Traceback (most recent call last):
  File "/home/airflow/.local/lib/python3.7/site-packages/airflow/operators/python.py", line 171, in execute
    return_value = self.execute_callable()
  File "/home/airflow/.local/lib/python3.7/site-packages/airflow/operators/python.py", line 189, in execute_callable
    return self.python_callable(*self.op_args, **self.op_kwargs)
  File "/opt/airflow/dags/newtest.py", line 107, in re
    result.append(ti.xcom_pull(task_ids='cr2'))
AttributeError: 'dict' object has no attribute 'xcom_pull'
[2022-08-11 23:33:39,891] {taskinstance.py:1420} INFO - Marking task as UP_FOR_RETRY. dag_id=craw, task_id=result, execution_date=20220810T145500, start_date=20220811T233324, end_date=20220811T233339
[2022-08-11 23:33:39,919] {standard_task_runner.py:97} ERROR - Failed to execute job 89 for task result ('dict' object has no attribute 'xcom_pull'; 29349)
[2022-08-11 23:33:39,938] {local_task_job.py:156} INFO - Task exited with return code 1
[2022-08-11 23:33:39,978] {local_task_job.py:273} INFO - 0 downstream tasks scheduled from follow-on schedule check
