[2022-08-11 02:17:20,318] {taskinstance.py:1179} INFO - Dependencies all met for <TaskInstance: fuck.fucking scheduled__2022-08-10T00:00:00+00:00 [queued]>
[2022-08-11 02:17:20,351] {taskinstance.py:1179} INFO - Dependencies all met for <TaskInstance: fuck.fucking scheduled__2022-08-10T00:00:00+00:00 [queued]>
[2022-08-11 02:17:20,352] {taskinstance.py:1376} INFO - 
--------------------------------------------------------------------------------
[2022-08-11 02:17:20,352] {taskinstance.py:1377} INFO - Starting attempt 1 of 1
[2022-08-11 02:17:20,354] {taskinstance.py:1378} INFO - 
--------------------------------------------------------------------------------
[2022-08-11 02:17:20,401] {taskinstance.py:1397} INFO - Executing <Task(PythonOperator): fucking> on 2022-08-10 00:00:00+00:00
[2022-08-11 02:17:20,411] {standard_task_runner.py:52} INFO - Started process 395 to run task
[2022-08-11 02:17:20,418] {standard_task_runner.py:79} INFO - Running: ['***', 'tasks', 'run', 'fuck', 'fucking', 'scheduled__2022-08-10T00:00:00+00:00', '--job-id', '48', '--raw', '--subdir', 'DAGS_FOLDER/tmp.py', '--cfg-path', '/tmp/tmpah54zs94', '--error-file', '/tmp/tmpwee1gun9']
[2022-08-11 02:17:20,419] {standard_task_runner.py:80} INFO - Job 48: Subtask fucking
[2022-08-11 02:17:20,555] {task_command.py:371} INFO - Running <TaskInstance: fuck.fucking scheduled__2022-08-10T00:00:00+00:00 [running]> on host d59619969b18
[2022-08-11 02:17:20,804] {taskinstance.py:1591} INFO - Exporting the following env vars:
AIRFLOW_CTX_DAG_OWNER=***
AIRFLOW_CTX_DAG_ID=fuck
AIRFLOW_CTX_TASK_ID=fucking
AIRFLOW_CTX_EXECUTION_DATE=2022-08-10T00:00:00+00:00
AIRFLOW_CTX_TRY_NUMBER=1
AIRFLOW_CTX_DAG_RUN_ID=scheduled__2022-08-10T00:00:00+00:00
[2022-08-11 02:17:20,809] {logger.py:11} INFO - ====== WebDriver manager ======
[2022-08-11 02:17:21,634] {logger.py:11} INFO - Get LATEST chromedriver version for google-chrome 104.0.5112
[2022-08-11 02:17:22,752] {logger.py:11} INFO - There is no [linux64] chromedriver for browser 104.0.5112 in cache
[2022-08-11 02:17:22,754] {logger.py:11} INFO - About to download new driver from https://chromedriver.storage.googleapis.com/104.0.5112.79/chromedriver_linux64.zip
[2022-08-11 02:17:29,310] {taskinstance.py:1909} ERROR - Task failed with exception
Traceback (most recent call last):
  File "/home/airflow/.local/lib/python3.7/site-packages/webdriver_manager/core/archive.py", line 39, in __extract_zip
    archive.extractall(to_directory)
  File "/usr/local/lib/python3.7/zipfile.py", line 1636, in extractall
    self._extract_member(zipinfo, path, pwd)
  File "/usr/local/lib/python3.7/zipfile.py", line 1691, in _extract_member
    shutil.copyfileobj(source, target)
  File "/usr/local/lib/python3.7/shutil.py", line 79, in copyfileobj
    buf = fsrc.read(length)
  File "/usr/local/lib/python3.7/zipfile.py", line 930, in read
    data = self._read1(n)
  File "/usr/local/lib/python3.7/zipfile.py", line 998, in _read1
    data += self._read2(n - len(data))
  File "/usr/local/lib/python3.7/zipfile.py", line 1033, in _read2
    raise EOFError
EOFError

During handling of the above exception, another exception occurred:

Traceback (most recent call last):
  File "/home/airflow/.local/lib/python3.7/site-packages/airflow/operators/python.py", line 171, in execute
    return_value = self.execute_callable()
  File "/home/airflow/.local/lib/python3.7/site-packages/airflow/operators/python.py", line 189, in execute_callable
    return self.python_callable(*self.op_args, **self.op_kwargs)
  File "/opt/airflow/dags/tmp.py", line 22, in ttt
    driver=webdriver.Chrome(ChromeDriverManager().install(),options=chrome_options)
  File "/home/airflow/.local/lib/python3.7/site-packages/webdriver_manager/chrome.py", line 38, in install
    driver_path = self._get_driver_path(self.driver)
  File "/home/airflow/.local/lib/python3.7/site-packages/webdriver_manager/core/manager.py", line 32, in _get_driver_path
    binary_path = self.driver_cache.save_file_to_cache(driver, file)
  File "/home/airflow/.local/lib/python3.7/site-packages/webdriver_manager/core/driver_cache.py", line 47, in save_file_to_cache
    files = archive.unpack(path)
  File "/home/airflow/.local/lib/python3.7/site-packages/webdriver_manager/core/archive.py", line 30, in unpack
    return self.__extract_zip(directory)
  File "/home/airflow/.local/lib/python3.7/site-packages/webdriver_manager/core/archive.py", line 41, in __extract_zip
    if e.args[0] not in [26, 13] and e.args[1] not in [
IndexError: tuple index out of range
[2022-08-11 02:17:29,349] {taskinstance.py:1420} INFO - Marking task as FAILED. dag_id=fuck, task_id=fucking, execution_date=20220810T000000, start_date=20220811T021720, end_date=20220811T021729
[2022-08-11 02:17:29,393] {standard_task_runner.py:97} ERROR - Failed to execute job 48 for task fucking (tuple index out of range; 395)
[2022-08-11 02:17:29,446] {local_task_job.py:156} INFO - Task exited with return code 1
[2022-08-11 02:17:29,502] {local_task_job.py:273} INFO - 0 downstream tasks scheduled from follow-on schedule check
