[2022-08-12 07:53:06,080] {taskinstance.py:1179} INFO - Dependencies all met for <TaskInstance: workflow.create_table scheduled__2022-08-11T00:00:00+00:00 [queued]>
[2022-08-12 07:53:06,096] {taskinstance.py:1179} INFO - Dependencies all met for <TaskInstance: workflow.create_table scheduled__2022-08-11T00:00:00+00:00 [queued]>
[2022-08-12 07:53:06,096] {taskinstance.py:1376} INFO - 
--------------------------------------------------------------------------------
[2022-08-12 07:53:06,097] {taskinstance.py:1377} INFO - Starting attempt 1 of 1
[2022-08-12 07:53:06,097] {taskinstance.py:1378} INFO - 
--------------------------------------------------------------------------------
[2022-08-12 07:53:06,130] {taskinstance.py:1397} INFO - Executing <Task(MySqlOperator): create_table> on 2022-08-11 00:00:00+00:00
[2022-08-12 07:53:06,139] {standard_task_runner.py:52} INFO - Started process 1326 to run task
[2022-08-12 07:53:06,145] {standard_task_runner.py:79} INFO - Running: ['***', 'tasks', 'run', 'workflow', 'create_table', 'scheduled__2022-08-11T00:00:00+00:00', '--job-id', '116', '--raw', '--subdir', 'DAGS_FOLDER/test.py', '--cfg-path', '/tmp/tmpiauxzpvb', '--error-file', '/tmp/tmp2eulbwa0']
[2022-08-12 07:53:06,146] {standard_task_runner.py:80} INFO - Job 116: Subtask create_table
[2022-08-12 07:53:06,305] {task_command.py:371} INFO - Running <TaskInstance: workflow.create_table scheduled__2022-08-11T00:00:00+00:00 [running]> on host d59619969b18
[2022-08-12 07:53:06,425] {taskinstance.py:1591} INFO - Exporting the following env vars:
AIRFLOW_CTX_DAG_OWNER=***
AIRFLOW_CTX_DAG_ID=workflow
AIRFLOW_CTX_TASK_ID=create_table
AIRFLOW_CTX_EXECUTION_DATE=2022-08-11T00:00:00+00:00
AIRFLOW_CTX_TRY_NUMBER=1
AIRFLOW_CTX_DAG_RUN_ID=scheduled__2022-08-11T00:00:00+00:00
[2022-08-12 07:53:06,426] {mysql.py:82} INFO - Executing: CREATE DATABASE qweql
[2022-08-12 07:53:06,453] {base.py:68} INFO - Using connection ID 'mysql_db' for task execution.
[2022-08-12 07:53:06,515] {dbapi.py:231} INFO - Running statement: CREATE DATABASE qweql, parameters: None
[2022-08-12 07:53:06,631] {dbapi.py:239} INFO - Rows affected: 1
[2022-08-12 07:53:06,656] {taskinstance.py:1420} INFO - Marking task as SUCCESS. dag_id=workflow, task_id=create_table, execution_date=20220811T000000, start_date=20220812T075306, end_date=20220812T075306
[2022-08-12 07:53:06,717] {local_task_job.py:156} INFO - Task exited with return code 0
[2022-08-12 07:53:06,782] {local_task_job.py:273} INFO - 0 downstream tasks scheduled from follow-on schedule check
[2022-08-13 08:22:47,976] {taskinstance.py:1179} INFO - Dependencies all met for <TaskInstance: workflow.create_table scheduled__2022-08-11T00:00:00+00:00 [queued]>
[2022-08-13 08:22:48,037] {taskinstance.py:1179} INFO - Dependencies all met for <TaskInstance: workflow.create_table scheduled__2022-08-11T00:00:00+00:00 [queued]>
[2022-08-13 08:22:48,052] {taskinstance.py:1376} INFO - 
--------------------------------------------------------------------------------
[2022-08-13 08:22:48,062] {taskinstance.py:1377} INFO - Starting attempt 1 of 1
[2022-08-13 08:22:48,063] {taskinstance.py:1378} INFO - 
--------------------------------------------------------------------------------
[2022-08-13 08:22:48,140] {taskinstance.py:1397} INFO - Executing <Task(MySqlOperator): create_table> on 2022-08-11 00:00:00+00:00
[2022-08-13 08:22:48,146] {standard_task_runner.py:52} INFO - Started process 339 to run task
[2022-08-13 08:22:48,162] {standard_task_runner.py:79} INFO - Running: ['***', 'tasks', 'run', 'workflow', 'create_table', 'scheduled__2022-08-11T00:00:00+00:00', '--job-id', '29', '--raw', '--subdir', 'DAGS_FOLDER/test.py', '--cfg-path', '/tmp/tmp9188m34c', '--error-file', '/tmp/tmpr8gfsi54']
[2022-08-13 08:22:48,163] {standard_task_runner.py:80} INFO - Job 29: Subtask create_table
[2022-08-13 08:22:48,340] {task_command.py:371} INFO - Running <TaskInstance: workflow.create_table scheduled__2022-08-11T00:00:00+00:00 [running]> on host cdb6935da655
[2022-08-13 08:22:48,670] {taskinstance.py:1591} INFO - Exporting the following env vars:
AIRFLOW_CTX_DAG_OWNER=***
AIRFLOW_CTX_DAG_ID=workflow
AIRFLOW_CTX_TASK_ID=create_table
AIRFLOW_CTX_EXECUTION_DATE=2022-08-11T00:00:00+00:00
AIRFLOW_CTX_TRY_NUMBER=1
AIRFLOW_CTX_DAG_RUN_ID=scheduled__2022-08-11T00:00:00+00:00
[2022-08-13 08:22:48,672] {mysql.py:82} INFO - Executing: CREATE DATABASE qweql
[2022-08-13 08:22:48,728] {taskinstance.py:1909} ERROR - Task failed with exception
Traceback (most recent call last):
  File "/home/airflow/.local/lib/python3.7/site-packages/airflow/providers/mysql/operators/mysql.py", line 84, in execute
    hook.run(self.sql, autocommit=self.autocommit, parameters=self.parameters)
  File "/home/airflow/.local/lib/python3.7/site-packages/airflow/hooks/dbapi.py", line 204, in run
    with closing(self.get_conn()) as conn:
  File "/home/airflow/.local/lib/python3.7/site-packages/airflow/providers/mysql/hooks/mysql.py", line 158, in get_conn
    conn = self.connection or self.get_connection(getattr(self, self.conn_name_attr))
  File "/home/airflow/.local/lib/python3.7/site-packages/airflow/hooks/base.py", line 67, in get_connection
    conn = Connection.get_connection_from_secrets(conn_id)
  File "/home/airflow/.local/lib/python3.7/site-packages/airflow/models/connection.py", line 430, in get_connection_from_secrets
    raise AirflowNotFoundException(f"The conn_id `{conn_id}` isn't defined")
airflow.exceptions.AirflowNotFoundException: The conn_id `mysql_db` isn't defined
[2022-08-13 08:22:48,741] {taskinstance.py:1420} INFO - Marking task as FAILED. dag_id=workflow, task_id=create_table, execution_date=20220811T000000, start_date=20220813T082247, end_date=20220813T082248
[2022-08-13 08:22:48,781] {standard_task_runner.py:97} ERROR - Failed to execute job 29 for task create_table (The conn_id `mysql_db` isn't defined; 339)
[2022-08-13 08:22:48,821] {local_task_job.py:156} INFO - Task exited with return code 1
[2022-08-13 08:22:48,918] {local_task_job.py:273} INFO - 0 downstream tasks scheduled from follow-on schedule check
